Workbook

Sheet ingresos
A1: TIPO | B1: CUFE/CUDE | C1: Folio | D1: Fecha Emisión | E1: NIT Emisor | F1: Nombre Emisor | G1: NIT Receptor | H1: Nombre Receptor | I1: SUBTOTAL | J1: IVA | K1: IC | L1: INC | M1: INC Bolsas | N1: Total
A2: Factura electrónica | B2: 0ca529a4eb298c18d480562f77e345f92b464cc18b8ccb83f0f630dabf30fc547ea3e4dd1d319d701ed16d92edad320e | C2: 1 | D2: 45722 | E2: 901907732 | F2: TECNOTICS SAS | G2: 811026805 | H2: PANACAMBIOS Y CIA LTDA | I2: =+N2-M2-L2-K2-J2 -> 550000 | J2: 104500 | K2: 0 | L2: 0 | M2: 0 | N2: 654500
A3: Factura electrónica | B3: bc7e4abaa565e3360dac35f42cccceb4bbbd3626328f38a5fd9e96a60a778981109b3b795d3b4ee0c5f505fe407e1cad | C3: 2 | D3: 45722 | E3: 901907732 | F3: TECNOTICS SAS | G3: 900208742 | H3: MAGNISEGUROS ASESORES EN SEGUROS LIMITADA | I3: =+N3-M3-L3-K3-J3 -> 200000 | J3: 0 | K3: 0 | L3: 0 | M3: 0 | N3: 200000
A4: Factura electrónica | B4: 287efd1111d9df3f1d35981d477437a3935829354fb79c214338a3cdfe104f0ebce51f0c4464a104b47ec9a2a5a848a9 | C4: 3 | D4: 45722 | E4: 901907732 | F4: TECNOTICS SAS | G4: 811044610 | H4: INGENIERIA HOSPITALARIA S.A.S | I4: =+N4-M4-L4-K4-J4 -> 650000 | J4: 123500 | K4: 0 | L4: 0 | M4: 0 | N4: 773500
A5: Factura electrónica | B5: d717c9894107f58afe544d83f3b04368108a1719b77d6e11c76005b9cbfbf90b39bca792850ceda3f2897f81696a223d | C5: 4 | D5: 45722 | E5: 901907732 | F5: TECNOTICS SAS | G5: 901495799 | H5: LUSEO COLOMBIA S.A.S | I5: =+N5-M5-L5-K5-J5 -> 1650000 | J5: 313500 | K5: 0 | L5: 0 | M5: 0 | N5: 1963500
A6: Factura electrónica | B6: 75231292c4b4a470e70655ca3e1b3b261d3a83e02be31336c3397365382a6404fb39a5ff3a5f293f457d1fb581f8f5bf | C6: 5 | D6: 45722 | E6: 901907732 | F6: TECNOTICS SAS | G6: 901495799 | H6: LUSEO COLOMBIA S.A.S | I6: =+N6-M6-L6-K6-J6 -> 1584738 | J6: 0 | K6: 0 | L6: 0 | M6: 0 | N6: 1584738
A7: Factura electrónica | B7: da965cc736422b2136d3bc9ee0868612c58cb1790bf29dbc23c90357a3088520b3d7db46e09fb537a4cd81b332f5c610 | C7: 6 | D7: 45722 | E7: 901907732 | F7: TECNOTICS SAS | G7: 830087371 | H7: TRANSPORTE ESPECIAL RUTA 07 S.A.S. | I7: =+N7-M7-L7-K7-J7 -> 1072018 | J7: 0 | K7: 0 | L7: 0 | M7: 0 | N7: 1072018
A8: Factura electrónica | B8: bb192f48ce7d0039100ee6d7941917e9c4d5a9bb2640566606ac037d2b5d064eada81e0e21e5ff54b00bc6f3bb4a4dbe | C8: 7 | D8: 45722 | E8: 901907732 | F8: TECNOTICS SAS | G8: 901774691 | H8: TIERRAFRIA ARQUITECTURA S.A.S | I8: =+N8-M8-L8-K8-J8 -> 367811 | J8: 0 | K8: 0 | L8: 0 | M8: 0 | N8: 367811
A9: Factura electrónica | B9: 1563a4b96c509c44e757f16d7ee724f24ad8e5a5054346260748fa259516f8cc2debf79afbcd04ea11127f5422cfe4a9 | C9: 8 | D9: 45722 | E9: 901907732 | F9: TECNOTICS SAS | G9: 900383497 | H9: INATHA S.A.S. | I9: =+N9-M9-L9-K9-J9 -> 430000 | J9: 81700 | K9: 0 | L9: 0 | M9: 0 | N9: 511700
A10: Factura electrónica | B10: 9a7a3c925620ebe9f7162021877c41ae22b92e44baf63770911041fb15e958d6569a624b68c2ce392dec9609012d7b4d | C10: 9 | D10: 45723 | E10: 901907732 | F10: TECNOTICS SAS | G10: 901884325 | H10: MEDELL?N DEVELOPMENT ECOSYSTEM S.A.S. | I10: =+N10-M10-L10-K10-J10 -> 367811 | J10: 0 | K10: 0 | L10: 0 | M10: 0 | N10: 367811
A11: Factura electrónica | B11: fa06717c752227527f2b35de5c770807ca37e91e0594607d2592904c5e532b7d9e0a86d28b261f4f5fa9915995384643 | C11: 10 | D11: 45910 | E11: 901907732 | F11: TECNOTICS SAS | G11: 117142370 | H11: Daniel Alejandro Martinez Velez | I11: =+N11-M11-L11-K11-J11 -> 100 | J11: 0 | K11: 0 | L11: 0 | M11: 0 | N11: 100
A12: Factura electrónica | B12: 187a7140782c15e4c06605f2b0a0043142850b893f8563f5e8cc9d149070522da5c0e579ec09f757bed4995a5094fbcc | C12: 10 | D12: 45723 | E12: 901907732 | F12: TECNOTICS SAS | G12: 900383497 | H12: INATHA S.A.S. | I12: =+N12-M12-L12-K12-J12 -> 430000 | J12: 0 | K12: 0 | L12: 0 | M12: 0 | N12: 430000
A13: Factura electrónica | B13: bf90fd36af5a60d3650d9a56d2ac9641fb543f230d2c09e3587f15faec491d844e96d1f419e2256abf3e4f2fe9e933f6 | C13: 12 | D13: 45910 | E13: 901907732 | F13: TECNOTICS SAS | G13: 117142370 | H13: Daniel Alejandro Martinez Velez | I13: =+N13-M13-L13-K13-J13 -> 100 | J13: 0 | K13: 0 | L13: 0 | M13: 0 | N13: 100
... A323: Factura electrónica | B323: 2c08dbc901779beeb0abac73c0a4e2072e210913f2b5c518de54c76ed9ea90e3d1dd1d06e61d04a853b3b60ef343b9f4 | C323: 317 | D323: 46021 | E323: 901907732 | F323: TECNOTICS SAS | G323: 811017918 | H323: FUMIAGRO S.A.S. | I323: =+N323-M323-L323-K323-J323 -> 6460000 | J323: 0 | K323: 0 | L323: 0 | M323: 0 | N323: 6460000
A324: Nota de crédito electrónica | B324: 6337f55a1f7bee8e17b6fd6a52d49da9ef1f875222dfd6037c781e9acc6ada0cb072de4681eb32c2a264df36a420ca54 | C324: NC21 | D324: 45723 | E324: 901907732 | F324: TECNOTICS SAS | G324: 901774691 | H324: TIERRAFRIA ARQUITECTURA S.A.S | I324: =+N324-M324-L324-K324-J324 -> -367811 | J324: 0 | K324: 0 | L324: 0 | M324: 0 | N324: -367811
A325: Nota de crédito electrónica | B325: 0962a335e07554d51ee7bdfac2a691ea5713985e9e1c9d83bc474cf3249c6ce191b099265a416358787b0c528501df97 | C325: NC210 | D325: 45870 | E325: 901907732 | F325: TECNOTICS SAS | G325: 900643097 | H325: HEMOGROUP S.A.S | I325: =+N325-M325-L325-K325-J325 -> -3110206 | J325: -218500 | K325: 0 | L325: 0 | M325: 0 | N325: -3328706
A326: Nota de crédito electrónica | B326: 4805a21884b61c4fda831bd82c76debecb1530f6b098bcab3b3d5260a8cb8f85a29d1b212644b171a640401b8dff2fa0 | C326: NC211 | D326: 45898 | E326: 901907732 | F326: TECNOTICS SAS | G326: 811044610 | H326: INGENIERIA HOSPITALARIA S.A.S | I326: =+N326-M326-L326-K326-J326 -> -8150000 | J326: -43700 | K326: 0 | L326: 0 | M326: 0 | N326: -8193700
A327: Nota de crédito electrónica | B327: 57e129a39630a44ae62e80b65aa7e982213cea72279af70ed534997ebedc618d33d7a7d2697cfec1edd19bc53797d98a | C327: NC212 | D327: 45940 | E327: 901907732 | F327: TECNOTICS SAS | G327: 830087371 | H327: TRANSPORTE ESPECIAL RUTA 07 S.A.S. | I327: =+N327-M327-L327-K327-J327 -> -16875000 | J327: 0 | K327: 0 | L327: 0 | M327: 0 | N327: -16875000
A328: Nota de crédito electrónica | B328: 9793693d019c9ab9cd1a27c53aab9e03fb42c6bb80606edb80108c87b41f1003e6526318c986ead641ec025d371157bf | C328: NC213 | D328: 45947 | E328: 901907732 | F328: TECNOTICS SAS | G328: 811000784 | H328: TERMINAL DEL SUR DE MEDELLIN PH | I328: =+N328-M328-L328-K328-J328 -> -456000 | J328: -86640 | K328: 0 | L328: 0 | M328: 0 | N328: -542640
A329: Nota de crédito electrónica | B329: 6a61e930a99d229bd24221bcccc26aa60aaa6b11fae51798eab72cab1f1bdd60e407afa8b8eff92f44208563d429c6e1 | C329: NC214 | D329: 45955 | E329: 901907732 | F329: TECNOTICS SAS | G329: 901344156 | H329: TRANS CONCORD TRAVEL S.A.S | I329: =+N329-M329-L329-K329-J329 -> -1550000 | J329: -57000 | K329: 0 | L329: 0 | M329: 0 | N329: -1607000
A330: Nota de crédito electrónica | B330: 0c4b839113e765fb7442cc03cd44630c5a0530e33769ef14f0e49190e659f9e28e5ee911e8606d51c6df0c9e26b0dee1 | C330: NC215 | D330: 45955 | E330: 901907732 | F330: TECNOTICS SAS | G330: 890910970 | H330: TRANSPORTES JERICO, PUEBLORICO, TARSO S.A.S. | I330: =+N330-M330-L330-K330-J330 -> -1550000 | J330: 0 | K330: 0 | L330: 0 | M330: 0 | N330: -1550000
A331: Nota de crédito electrónica | B331: 41163a4559d4a60e00d26ac513fc6677f289985fa77066283f2dadebeb10f761a22eeb52109512547243e4d19ea05a3c | C331: NC216 | D331: 45963 | E331: 901907732 | F331: TECNOTICS SAS | G331: 901225179 | H331: INNOVACIÓN ESTRATÉGICA - INNOVATE S.A.S. | I331: =+N331-M331-L331-K331-J331 -> -868854 | J331: 0 | K331: 0 | L331: 0 | M331: 0 | N331: -868854
A332: Nota de crédito electrónica | B332: e76db0627546ce847a644d55c9cdb1dc026a6910a97ba9c741ccb63128a906991a853bb874ed350c2982b9295874ed8c | C332: NC217 | D332: 45973 | E332: 901907732 | F332: TECNOTICS SAS | G332: 900688446 | H332: CONSTRUREDES GRUPO GOMEZ | I332: =+N332-M332-L332-K332-J332 -> -1020000 | J332: -193800 | K332: 0 | L332: 0 | M332: 0 | N332: -1213800
A333: Nota de crédito electrónica | B333: 7a8ffb4f608d05c82cae350daf681dd91a0c4ba0391349c142ee01efc2e7c24cfa65a024acfa6fb48fae3450fa7920b8 | C333: NC218 | D333: 45975 | E333: 901907732 | F333: TECNOTICS SAS | G333: 900688446 | H333: CONSTRUREDES GRUPO GOMEZ | I333: =+N333-M333-L333-K333-J333 -> -1244546.2 | J333: -236463.78 | K333: 0 | L333: 0 | M333: 0 | N333: -1481010
A334: Nota de crédito electrónica | B334: 6a7423df234b0703d5e63b72a4dd47fe99b6bb07c3cbfe6322ac267ccfb9add3591c8a7ec804a123d3f0b07a37ff5263 | C334: NC219 | D334: 45990 | E334: 901907732 | F334: TECNOTICS SAS | G334: 900742678 | H334: LIFEHEALTH UNIVERSAL EXPORT SAS | I334: =+N334-M334-L334-K334-J334 -> -650000 | J334: -123500 | K334: 0 | L334: 0 | M334: 0 | N334: -773500
A335: Nota de crédito electrónica | B335: 0aab57ed6fd68ee08c575bae8d787268f60738dc0db999b3ecf18ede1ef7d6635b168bd0753ae8431fae98935077e58a | C335: NC22 | D335: 45723 | E335: 901907732 | F335: TECNOTICS SAS | G335: 900383497 | H335: INATHA S.A.S. | I335: =+N335-M335-L335-K335-J335 -> -430000 | J335: -81700 | K335: 0 | L335: 0 | M335: 0 | N335: -511700
... A342: Nota de crédito electrónica | B342: 6eee1740a9991f4923e40505e83ee7ebe63eb9df702703a0f13f36ddcfadd88a8e136848120248e8ff0234200aefd666 | C342: NC29 | D342: 45856 | E342: 901907732 | F342: TECNOTICS SAS | G342: 900825963 | H342: IDINNOV S.A.S. | I342: =+N342-M342-L342-K342-J342 -> -338919 | J342: -23750 | K342: 0 | L342: 0 | M342: 0 | N342: -362669
I343: =SUM(I2:I342) -> 5.1584656e+08 | J343: =SUM(J2:J342) -> 44511560 | K343: =SUM(K2:K342) -> 0 | L343: =SUM(L2:L342) -> 0 | M343: =SUM(M2:M342) -> 0 | N343: =SUM(N2:N342) -> 5.6035812e+08

Sheet Hoja3ok
A1: Suma de SUBTOTAL | C1: TIPO
A2: NIT Receptor | B2: Nombre Receptor | C2: Factura electrónica | D2: Nota de crédito electrónica | E2: Total general
A3: 21993269 | B3: I.E El Rosario de Bello | C3: 12862964 | E3: 12862964 | F3: sin retencion
A4: 98532400 | B4: Juan David Sánchez López | C4: 2483000 | E4: 2483000 | F4: sin retencion
A5: 117142370 | B5: Daniel Alejandro Martinez Velez | C5: 500 | E5: 500 | F5: sin retencion
A6: 811000784 | B6: TERMINAL DEL SUR DE MEDELLIN PH | C6: 62247339 | D6: -456000 | E6: 61791339
A7: 811017918 | B7: FUMIAGRO S.A.S. | C7: 20771712 | E7: 20771712
A8: 811026805 | B8: PANACAMBIOS Y CIA LTDA | C8: 5500000 | E8: 5500000
A9: 811035110 | B9: CI Global Exchange SAS | C9: 545000 | E9: 545000
A10: 811044610 | B10: INGENIERIA HOSPITALARIA S.A.S | C10: 26846920 | D10: -8150000 | E10: 18696920
A11: 830087371 | B11: TRANSPORTE ESPECIAL RUTA 07 S.A.S. | C11: 41933068 | D11: -16875000 | E11: 25058068
A12: 860022343 | B12: CONGREGACION SANTO DOMINGO | C12: 62700751 | E12: 62700751
A13: 890910970 | B13: TRANSPORTES JERICO, PUEBLORICO, TARSO S.A.S. | C13: 21211744 | D13: -1550000 | E13: 19661744
A14: 890911898 | B14: Stop SAS | C14: 2445000 | E14: 2445000
A15: 890931488 | B15: CENTRO COMERCIAL VILLANUEVA P.H. | C15: 900000 | E15: 900000
A16: 890932241 | B16: TECNIQUIMICASA | C16: 160000 | E16: 160000
A17: 890935751 | B17: LENTES DE CONTACTO S.A.S. | C17: 620000 | E17: 620000
A18: 900177076 | B18: vista norte sas | C18: 1405000 | E18: 1405000
A19: 900208742 | B19: MAGNISEGUROS ASESORES EN SEGUROS LIMITADA | C19: 4140000 | D19: -780000 | E19: 3360000
A20: 900383497 | B20: INATHA S.A.S. | C20: 4752389 | D20: -430000 | E20: 4322389
A21: 900643097 | B21: HEMOGROUP S.A.S | C21: 41395178 | D21: -3110206 | E21: 38284972
A22: 900688446 | B22: CONSTRUREDES GRUPO GOMEZ | C22: 25009856 | D22: -2264546.2 | E22: 22745310
A23: 900727888 | B23: ARRENDAMIENTOS PANORAMA LOS COLORES SAS | C23: 1468240 | E23: 1468240
A24: 900742678 | B24: LIFEHEALTH UNIVERSAL EXPORT SAS | C24: 650000 | D24: -650000 | E24: 0
A25: 900779955 | B25: COMERCIALIZADORA INTERNACIONAL EXUN S.A.S | C25: 3099000 | E25: 3099000
A26: 900825963 | B26: IDINNOV S.A.S. | C26: 1576158 | D26: -927838 | E26: 648320
A27: 900842157 | B27: GRUPO ODONTOLÓGICO SMILE S.A.S | C27: 2408828 | E27: 2408828
A28: 900983772 | B28: VIBART DENTAL CLINIC | C28: 2917782 | E28: 2917782
A29: 901094323 | B29: GIGA ELECTROINGENIERIA SAS | C29: 1800000 | E29: 1800000
A30: 901105552 | B30: 24 H SERVICES S.A.S | C30: 81107275 | E30: 81107275
A31: 901174894 | B31: GILESA SAS | C31: 1867624 | E31: 1867624
A32: 901193232 | B32: SIMA TECH SAS | C32: 1918070 | E32: 1918070
A33: 901196517 | B33: Mas 3 Inmobiliaria SAS | C33: 840000 | E33: 840000
A34: 901225179 | B34: INNOVACIÓN ESTRATÉGICA - INNOVATE S.A.S. | C34: 6950832 | D34: -868854 | E34: 6081978
A35: 901344156 | B35: TRANS CONCORD TRAVEL S.A.S | C35: 17007000 | D35: -1550000 | E35: 15457000
A36: 901428649 | B36: ELECTROMANTENIMIENTO A.C S.A.S | C36: 9156404 | E36: 9156404
A37: 901446911 | B37: DALIAS GROUP S.A.S. | C37: 1161630 | E37: 1161630
A38: 901495799 | B38: LUSEO COLOMBIA S.A.S | C38: 71537872 | D38: -2128439 | E38: 69409433
A39: 901586731 | B39: SOPORTES TECHNOLOGY SAS | C39: 2690000 | E39: 2690000
A40: 901774691 | B40: TIERRAFRIA ARQUITECTURA S.A.S | C40: 4055025 | D40: -1860339 | E40: 2194686
...

Sheet Costos
A1: TIPO | B1: CUFE/CUDE | C1: Folio | D1: Fecha Emisión | E1: NIT Emisor | F1: Nombre Emisor | G1: NIT Receptor | H1: Nombre Receptor | I1: SUBTOTAL | J1: IVA | K1: IC | L1: INC | M1: INC Bolsas | N1: Total
A2: Factura electrónica | B2: e28c09b7699f692230f516beb9b2781f68209a3b04f9b0fc7cba231a8d521792b9fed3c89292e12ed5b4b7b13002d8be | C2: 595069 | D2: 46021 | E2: 800091549 | F2: IMPRESISTEM S A S | G2: 901907732 | H2: TECNOTICS S.A.S. | I2: 289879 | J2: 55077 | K2: 0 | L2: 0 | M2: 0 | N2: 344956
A3: Factura electrónica | B3: ebe95ec7444370efd7a552502fcf29930fcfece6b2b1d8f4d2bdaf209f7425942e2d46552cfa1e06394fe23d108c770b | C3: 954 | D3: 46021 | E3: 901649254 | F3: JSA DISTRIBUCIONES S.A.S. | G3: 901907732 | H3: TECNOTICS S.A.S. | I3: 16114196 | J3: 3061697.2 | K3: 0 | L3: 0 | M3: 0 | N3: 19175893
A4: Factura electrónica | B4: c76dc187c2f78bd833cb701d006628ee54dc3ba62b7136fb89cea1222ed9b2f098fb48ba326cf3b0969a9198987e28c5 | C4: 83 | D4: 46021 | E4: 1003880015 | F4: PAEZ BALLESTEROS CESAR NICOLAS | G4: 901907732 | H4: TECNOTICS SAS | I4: 80000 | J4: 0 | K4: 0 | L4: 0 | M4: 0 | N4: 80000
A5: Factura electrónica | B5: 74b000d75141dc8628c2ba82f6be3da8f1cc9a8bbd76957206b138ac2ad60702b87b4c85cdc7c156f46f2675b65e4561 | C5: 2961 | D5: 46020 | E5: 70561688 | F5: DIEGO ALONSO MURILLO GUZMAN | G5: 901907732 | H5: TECNOTICS SAS | I5: 16000 | J5: 3040 | K5: 0 | L5: 0 | M5: 0 | N5: 19040
A6: Factura electrónica | B6: df22eb1c87b063255405c75c901219dbff066c1a68594d36f17f5bf36a866d7f7d289b55d3f96a12a5318727d0fd30ae | C6: 79837 | D6: 46020 | E6: 900848266 | F6: CONSMO PC MAYORISTA S.A.S | G6: 901907732 | H6: TECNOTICS SAS | I6: 20000 | J6: 3800 | K6: 0 | L6: 0 | M6: 0 | N6: 23800
A7: Factura electrónica | B7: 6c5a072ec87f3488df2a1c0dcbfad8165fa8b384868fe403bab6c3dc7cf99f108e7b4ce5bf1fd8b8fc806f97f19a37f8 | C7: 4256 | D7: 46020 | E7: 3486666 | F7: RAMON ALCIDES CIFUENTES SERNA | G7: 901907732 | H7: TECNOTICS SAS | I7: 20000 | J7: 0 | K7: 0 | L7: 0 | M7: 0 | N7: 20000
A8: Factura electrónica | B8: 9ecf7a065b0598de8815ebdab0a1a977eb6b2e49ef4891d8d866f7490009f8add0399b551298eff88151de53c282fee4 | C8: 729528 | D8: 46015 | E8: 900219834 | F8: F2X S.A.S. | G8: 901907732 | H8: Tecnotics S.A.S | I8: 3781.51 | J8: 718.49 | K8: 0 | L8: 0 | M8: 0 | N8: 4500
A9: Factura electrónica | B9: b10c4fc37a4d66b8c8e3ba04389cb2cc95669bf3fa36c9a6d5b43d0f2776a3a661f4b711f8be659c870db28286e2dae4 | C9: 720444 | D9: 46014 | E9: 900219834 | F9: F2X S.A.S. | G9: 901907732 | H9: Tecnotics S.A.S | I9: 3781.51 | J9: 718.49 | K9: 0 | L9: 0 | M9: 0 | N9: 4500
A10: Documento equivalente - Cobro de peajes | B10: 4cc16ba17f6702d3cdbbbce7fcd53948b186663c63ce33f0f849c999f2adea320a4de4d5a45692a381fad43f8c10982c | C10: 75584379 | D10: 46014 | E10: 900219834 | F10: F2X S.A.S. | G10: 901907732 | H10: Tecnotics S.A.S | I10: 25000 | J10: 0 | K10: 0 | L10: 0 | M10: 0 | N10: 25000
A11: Documento equivalente - Cobro de peajes | B11: 57a1dded2b2cc9efb7d6f48f4d0c9d6967087a8982e1148b1c06f260d81ecab36291300288c903eb43700c0471b12383 | C11: 75544794 | D11: 46014 | E11: 900219834 | F11: F2X S.A.S. | G11: 901907732 | H11: Tecnotics S.A.S | I11: 25000 | J11: 0 | K11: 0 | L11: 0 | M11: 0 | N11: 25000
A12: Factura electrónica | B12: 7fd460ab1ee66ef439559490c092235e92215e22771a1274081de0ee4558dff68aa3b0e51e4038ee2f384b36cbe7d046 | C12: 907 | D12: 46014 | E12: 901649254 | F12: JSA DISTRIBUCIONES S.A.S. | G12: 901907732 | H12: TECNOTICS S.A.S. | I12: 2338676.5 | J12: 444348.53 | K12: 0 | L12: 0 | M12: 0 | N12: 2783025
A13: Factura electrónica | B13: d2d556c9e420610eb62d728be7080a820149b06428682cef711712df243d5848d1ce21af6592f412ed76e716baab0541 | C13: 703430 | D13: 46014 | E13: 900219834 | F13: F2X S.A.S. | G13: 901907732 | H13: Tecnotics S.A.S | I13: 3361.35 | J13: 638.65 | K13: 0 | L13: 0 | M13: 0 | N13: 4000
... A24: Factura electrónica | B24: f5f77d4ac7f0c7f64966ffdf96e444d8914e46c20d461975e20b4e616502fbe33434afef8f84f6b4a0d20af4bf5e0e90 | C24: 883 | D24: 46010 | E24: 901649254 | F24: JSA DISTRIBUCIONES S.A.S. | G24: 901907732 | H24: TECNOTICS S.A.S. | I24: 1860083.6 | J24: 353415.88 | K24: 0 | L24: 0 | M24: 0 | N24: 2213499.5
A25: Factura electrónica | B25: bfb6492b1b4dcfa1697749cfd7a4e98e7ac345596f7f4cb993566495e8ce4d0558f06e3b8f7b7ae5e649e3a0c93ee08f | C25: 13206 | D25: 46010 | E25: 700108357 | F25: STEFANO ZINNO | G25: 901907732 | H25: tecnotics S.A.S. | I25: 235500 | J25: 0 | K25: 0 | L25: 0 | M25: 0 | N25: 235500 | O25: =+I25*3.5% -> 8242.5
A26: Factura electrónica | B26: c667311bba11f05ee0a408284e735fade9e833041d55eb2bce7eef4419c9fc195229683221f9027c81b5fe65d45a3888 | C26: 17846 | D26: 46010 | E26: 901476410 | F26: GRUPO LEDACOM SAS | G26: 901907732 | H26: TECNOTICS SAS | I26: 24706 | J26: 4694 | K26: 0 | L26: 0 | M26: 0 | N26: 29400 | O26: =+I26*2.5% -> 617.65
A27: Factura electrónica | B27: 17af339e7b8e6d79d6ec114bc963c755a1696df827b77c87671d6b1fbdd1fe745ce97108e33af4d1db2f2c1c5de81517 | C27: 874 | D27: 46009 | E27: 901649254 | F27: JSA DISTRIBUCIONES S.A.S. | G27: 901907732 | H27: TECNOTICS S.A.S. | I27: 3632352.8 | J27: 690147.04 | K27: 0 | L27: 0 | M27: 0 | N27: 4322499.9
A28: Factura electrónica | B28: 5cc10645d6fa08e426da11dd5ae7525a36fa5ef01e3a532966bdf03093318c88a6385b43842c73bf14ad5168af1c8fde | C28: 33384 | D28: 46008 | E28: 901161479 | F28: IDT COLOMBIA SAS | G28: 901907732 | H28: TECNOTICS SAS | I28: 2037560 | J28: 387136.4 | K28: 0 | L28: 0 | M28: 0 | N28: 2424696.4
A29: Factura electrónica | B29: a4b89aef16f675b32b5b37561dd7e98e2799be236e8e588b48664298280a247a7bb4a7de6bf924da22c4786951db3b67 | C29: 592685 | D29: 46008 | E29: 800091549 | F29: IMPRESISTEM S A S | G29: 901907732 | H29: TECNOTICS S.A.S. | I29: 1612896 | J29: 0 | K29: 0 | L29: 0 | M29: 0 | N29: 1612896
A30: Factura electrónica | B30: c8928927314f4ab63f8d04b887e99be5a61b1f85212c8ba9c0d34a540553c516e5d4aeff2a42dcea04e36b9e981b1253 | C30: 592620 | D30: 46008 | E30: 800091549 | F30: IMPRESISTEM S A S | G30: 901907732 | H30: TECNOTICS S.A.S. | I30: 311728 | J30: 0 | K30: 0 | L30: 0 | M30: 0 | N30: 311728
A31: Factura electrónica | B31: 8902454e8f65653647b70196e12a1c6c7f26dfd079d1b062d5f757acbc8c5de760eb478ddf8b9f8b8266431e6b840396 | C31: 592619 | D31: 46008 | E31: 800091549 | F31: IMPRESISTEM S A S | G31: 901907732 | H31: TECNOTICS S.A.S. | I31: 468383 | J31: 0 | K31: 0 | L31: 0 | M31: 0 | N31: 468383
A32: Factura electrónica | B32: 936fbeea12c8b3d8db4cc8560cd8dc3af4babfa992f7d1406d03b7e136b025c9669e366ec68bf0846da96ba8197ba39d | C32: 592618 | D32: 46008 | E32: 800091549 | F32: IMPRESISTEM S A S | G32: 901907732 | H32: TECNOTICS S.A.S. | I32: 548978 | J32: 0 | K32: 0 | L32: 0 | M32: 0 | N32: 548978
A33: Factura electrónica | B33: 5d85a4d682574ddd2fccf652aa7bb7a72704e8dfeb6a70549f873e347973b58fe59b9447edd5748d4b19dee7a935bf87 | C33: 592616 | D33: 46008 | E33: 800091549 | F33: IMPRESISTEM S A S | G33: 901907732 | H33: TECNOTICS S.A.S. | I33: 229559 | J33: 0 | K33: 0 | L33: 0 | M33: 0 | N33: 229559
A34: Factura electrónica | B34: e902586e468724baa9edf3198828b5babda7c8fc21eb03e4ed0449b0bff2ccf437753d64e3fe2025737708816a967e57 | C34: 592615 | D34: 46008 | E34: 800091549 | F34: IMPRESISTEM S A S | G34: 901907732 | H34: TECNOTICS S.A.S. | I34: 135780 | J34: 0 | K34: 0 | L34: 0 | M34: 0 | N34: 135780
A35: Factura electrónica | B35: 2ecb4b0dd903a151cb1d8f902887b62e5dd5702e7bb2d1c937d3eb2494872bc639a915c5cf8b9823951750d85d6ec6dc | C35: 592614 | D35: 46008 | E35: 800091549 | F35: IMPRESISTEM S A S | G35: 901907732 | H35: TECNOTICS S.A.S. | I35: 23266 | J35: 0 | K35: 0 | L35: 0 | M35: 0 | N35: 23266
A36: Factura electrónica | B36: 1ab8767e4d089fdfb38c23fc5cb39a184f0c6bd75d49c2999870943ff6d4666f634e74e97cc570ad72607859e2d03ebf | C36: 592612 | D36: 46008 | E36: 800091549 | F36: IMPRESISTEM S A S | G36: 901907732 | H36: TECNOTICS S.A.S. | I36: 332984 | J36: 0 | K36: 0 | L36: 0 | M36: 0 | N36: 332984
A37: Factura electrónica | B37: 96fbd8d6a63b72e65f74927a50984d8283be221b2fbbd25c319fb840cf9599770dcff690cd2e3c647c82a213a64591f1 | C37: 592611 | D37: 46008 | E37: 800091549 | F37: IMPRESISTEM S A S | G37: 901907732 | H37: TECNOTICS S.A.S. | I37: 763843 | J37: 0 | K37: 0 | L37: 0 | M37: 0 | N37: 763843
A38: Factura electrónica | B38: c259c6c915e70f1e1a6a4aca7e24eb5d1e8bf2c0da3b6819d0042501bd39298cc74d07b17bd50798fcee2ae4bba7e0b5 | C38: 592610 | D38: 46008 | E38: 800091549 | F38: IMPRESISTEM S A S | G38: 901907732 | H38: TECNOTICS S.A.S. | I38: 127294 | J38: 0 | K38: 0 | L38: 0 | M38: 0 | N38: 127294
... A52: Factura electrónica | B52: 90ed1b2adaef48716c4f3be5946c63162ca0b5ec484077b94814c93b4f90fd26b345627d48df1f453a59e3efc68c1d05 | C52: 150179 | D52: 46003 | E52: 811000784 | F52: TERMINAL SUR DE MEDELLIN PH | G52: 901907732 | H52: TECNO TIC SAS | I52: 3529.41 | J52: 670.59 | K52: 0 | L52: 0 | M52: 0 | N52: 4200
A53: Factura electrónica | B53: f33d71968fa3b5e0bd4b52ef2838a2698ab87c56e1c2dd5eb34463920ecdb80d56e21959761a8c14728a3eaffa79a685 | C53: 198799 | D53: 46003 | E53: 901192317 | F53: SYSCOM COLOMBIA SAS | G53: 901907732 | H53: TECNOTICS SAS | I53: 534715.61 | J53: 101597 | K53: 0 | L53: 0 | M53: 0 | N53: 636312.61 | O53: =+I53*2.5% -> 13367.89
A54: Factura electrónica | B54: e97b2622cf247aeb997f7ae817f354872d23666564a78ee718bbf5272c3a9035dde74f32b0e5aa21601ff90e83228df8 | C54: 13184 | D54: 46003 | E54: 700108357 | F54: STEFANO ZINNO | G54: 901907732 | H54: tecnotics S.A.S. | I54: 159000 | J54: 0 | K54: 0 | L54: 0 | M54: 0 | N54: 159000 | O54: =+I54*3.5% -> 5565
A55: Factura electrónica | B55: 9037cab86c844c2cf159c07723bf8efbdf2734f112aced6702905349d82882ab4f600a75f24d4da1e51cf3831957fa61 | C55: 849 | D55: 46003 | E55: 901649254 | F55: JSA DISTRIBUCIONES S.A.S. | G55: 901907732 | H55: TECNOTICS S.A.S. | I55: 7563024 | J55: 1436974.6 | K55: 0 | L55: 0 | M55: 0 | N55: 8999998.6
A56: Factura electrónica | B56: c994bfd9927ab394e2343ebc2367f882916674edd14c9bb82f1e2b1780c54b041127289165952b1adff8ca1bfa657be7 | C56: 464594 | D56: 46002 | E56: 900219834 | F56: F2X S.A.S. | G56: 901907732 | H56: Tecnotics S.A.S | I56: 3781.51 | J56: 718.49 | K56: 0 | L56: 0 | M56: 0 | N56: 4500
A57: Factura electrónica | B57: d812e3801c68f1f5630ec0d5820487cf4af75417d50efa9c60177143bd2bcbf41d5644266c695f1a9ef06d23d8df0992 | C57: 163535970 | D57: 46002 | E57: 830114921 | F57: COLOMBIA MOVIL S.A. ESP | G57: 901907732 | H57: TECNOTICS SAS | I57: 6302.59 | J57: 1197.41 | K57: 0 | L57: 0 | M57: 0 | N57: 7500
A58: Factura electrónica | B58: 1647e4bed00eb05f04bc0cf236bc827697dca663b2cb13ebdb369978a481ffc34bf9847de10f01f692afcb043050eaa1 | C58: 8886341 | D58: 46001 | E58: 900219834 | F58: F2X S.A.S. | G58: 901907732 | H58: Tecnotics S.A.S | I58: 3739.51 | J58: 710.49 | K58: 0 | L58: 0 | M58: 0 | N58: 4450
A59: Factura electrónica | B59: 5dc4f16893dcf903e0957949789752cf4ffa842d82d0c4eb50dbf1ee287dd9c75ed3f150a649711d1074f2359973c924 | C59: 437529 | D59: 46001 | E59: 900219834 | F59: F2X S.A.S. | G59: 901907732 | H59: Tecnotics S.A.S | I59: 6554.62 | J59: 1245.38 | K59: 0 | L59: 0 | M59: 0 | N59: 7800
A60: Factura electrónica | B60: a41198a53630897ff7bc481d2642cbd3212210998441d4f4f2e0c3898a955c86fbbdd7aff44fe05e554142eb52d798fa | C60: 208497 | D60: 45997 | E60: 890941794 | F60: FRANCISCO MURILLO S.A.S. | G60: 901907732 | H60: TECNOTICS SAS | I60: 215500 | J60: 40945 | K60: 0 | L60: 0 | M60: 0 | N60: 256445
A61: Factura electrónica | B61: 7d1d8210918fdaff3e839a75d4df02037e85d4a4f39f4517200846fd05d61f4a4d3b016e5758c27b33dc905a2ba5d8c2 | C61: 4320 | D61: 45997 | E61: 901421223 | F61: ILUMINACIONES ANTIOQUIA SAS | G61: 901907732 | H61: TECNOTICS SAS | I61: 151260.5 | J61: 28739.5 | K61: 0 | L61: 0 | M61: 0 | N61: 180000
A62: Factura electrónica | B62: 26c7122f3f5128f21b819210525a384920961e6181bb13284a5b53a13a61e2cffaa28eadae7099db07337501c6ff4a21 | C62: 362477 | D62: 45996 | E62: 900219834 | F62: F2X S.A.S. | G62: 901907732 | H62: Tecnotics S.A.S | I62: 5042.02 | J62: 957.98 | K62: 0 | L62: 0 | M62: 0 | N62: 6000
A63: Factura electrónica | B63: c2bfd1fbcafe97515ac8d69ddcd40f81e7548b190390b800cdf5cc277a747bc4d02ec0ac04b8e6e5d0b71d6438af9d92 | C63: 36051 | D63: 45996 | E63: 901051870 | F63: D4 FIT WEAR S.A.S | G63: 901907732 | H63: Alejandro Martinez | I63: 112689.08 | J63: 4310.92 | K63: 0 | L63: 0 | M63: 0 | N63: 117000
...

Sheet Análisis Costos
A1: ANÁLISIS DE COSTOS MENSUALES — TECNOTICS S.A.S.
A2: Fuente: hoja Costos (facturas de compra, feb–dic 2025). Valores en COP.
A4: Mes | B4: # Facturas | C4: Subtotal | D4: IVA | E4: Total | F4: % del Total | H4: Top 10 Proveedores | I4: NIT | J4: # Facturas | K4: Total | L4: % del Total
A5: =DATE(2025,2,1) -> 45689 | B5: =COUNTIFS(Costos!$D:$D,">="&A5,Costos!$D:$D,"<"&EDATE(A5,1)) -> 15 | C5: =SUMIFS(Costos!$I:$I,Costos!$D:$D,">="&A5,Costos!$D:$D,"<"&EDATE(A5,1)) -> 13646284 | D5: =SUMIFS(Costos!$J:$J,Costos!$D:$D,">="&A5,Costos!$D:$D,"<"&EDATE(A5,1)) -> 0 | E5: =SUMIFS(Costos!$N:$N,Costos!$D:$D,">="&A5,Costos!$D:$D,"<"&EDATE(A5,1)) -> 13646284 | F5: =IFERROR(E5/$E$16,0) -> 0.035534878 | H5: IMPRESISTEM S A S | I5: 800091549 | J5: =COUNTIFS(Costos!$E:$E,I5) -> 162 | K5: =SUMIFS(Costos!$N:$N,Costos!$E:$E,I5) -> 166259481 | L5: =IFERROR(K5/$E$16,0) -> 0.43293913
A6: =EDATE(A5,1) -> 45717 | B6: =COUNTIFS(Costos!$D:$D,">="&A6,Costos!$D:$D,"<"&EDATE(A6,1)) -> 28 | C6: =SUMIFS(Costos!$I:$I,Costos!$D:$D,">="&A6,Costos!$D:$D,"<"&EDATE(A6,1)) -> 20366241 | D6: =SUMIFS(Costos!$J:$J,Costos!$D:$D,">="&A6,Costos!$D:$D,"<"&EDATE(A6,1)) -> 1397966.6 | E6: =SUMIFS(Costos!$N:$N,Costos!$D:$D,">="&A6,Costos!$D:$D,"<"&EDATE(A6,1)) -> 21764207 | F6: =IFERROR(E6/$E$16,0) -> 0.056673923 | H6: JSA DISTRIBUCIONES S.A.S. | I6: 901649254 | J6: =COUNTIFS(Costos!$E:$E,I6) -> 10 | K6: =SUMIFS(Costos!$N:$N,Costos!$E:$E,I6) -> 62141981 | L6: =IFERROR(K6/$E$16,0) -> 0.16181751
A7: =EDATE(A6,1) -> 45748 | B7: =COUNTIFS(Costos!$D:$D,">="&A7,Costos!$D:$D,"<"&EDATE(A7,1)) -> 47 | C7: =SUMIFS(Costos!$I:$I,Costos!$D:$D,">="&A7,Costos!$D:$D,"<"&EDATE(A7,1)) -> 55238334 | D7: =SUMIFS(Costos!$J:$J,Costos!$D:$D,">="&A7,Costos!$D:$D,"<"&EDATE(A7,1)) -> 1783437.4 | E7: =SUMIFS(Costos!$N:$N,Costos!$D:$D,">="&A7,Costos!$D:$D,"<"&EDATE(A7,1)) -> 57100357 | F7: =IFERROR(E7/$E$16,0) -> 0.14868914 | H7: GRUPO LEDACOM SAS | I7: 901476410 | J7: =COUNTIFS(Costos!$E:$E,I7) -> 43 | K7: =SUMIFS(Costos!$N:$N,Costos!$E:$E,I7) -> 27995900 | L7: =IFERROR(K7/$E$16,0) -> 0.07290123
A8: =EDATE(A7,1) -> 45778 | B8: =COUNTIFS(Costos!$D:$D,">="&A8,Costos!$D:$D,"<"&EDATE(A8,1)) -> 38 | C8: =SUMIFS(Costos!$I:$I,Costos!$D:$D,">="&A8,Costos!$D:$D,"<"&EDATE(A8,1)) -> 22788363 | D8: =SUMIFS(Costos!$J:$J,Costos!$D:$D,">="&A8,Costos!$D:$D,"<"&EDATE(A8,1)) -> 578569.4 | E8: =SUMIFS(Costos!$N:$N,Costos!$D:$D,">="&A8,Costos!$D:$D,"<"&EDATE(A8,1)) -> 23382555 | F8: =IFERROR(E8/$E$16,0) -> 0.060888095 | H8: SYSCOM COLOMBIA SAS | I8: 901192317 | J8: =COUNTIFS(Costos!$E:$E,I8) -> 22 | K8: =SUMIFS(Costos!$N:$N,Costos!$E:$E,I8) -> 27900207 | L8: =IFERROR(K8/$E$16,0) -> 0.072652046
A9: =EDATE(A8,1) -> 45809 | B9: =COUNTIFS(Costos!$D:$D,">="&A9,Costos!$D:$D,"<"&EDATE(A9,1)) -> 36 | C9: =SUMIFS(Costos!$I:$I,Costos!$D:$D,">="&A9,Costos!$D:$D,"<"&EDATE(A9,1)) -> 18882528 | D9: =SUMIFS(Costos!$J:$J,Costos!$D:$D,">="&A9,Costos!$D:$D,"<"&EDATE(A9,1)) -> 204863.51 | E9: =SUMIFS(Costos!$N:$N,Costos!$D:$D,">="&A9,Costos!$D:$D,"<"&EDATE(A9,1)) -> 19090198 | F9: =IFERROR(E9/$E$16,0) -> 0.049710811 | H9: KASKEY COLOMBIA SAS | I9: 901334425 | J9: =COUNTIFS(Costos!$E:$E,I9) -> 2 | K9: =SUMIFS(Costos!$N:$N,Costos!$E:$E,I9) -> 14327985 | L9: =IFERROR(K9/$E$16,0) -> 0.037310024
A10: =EDATE(A9,1) -> 45839 | B10: =COUNTIFS(Costos!$D:$D,">="&A10,Costos!$D:$D,"<"&EDATE(A10,1)) -> 62 | C10: =SUMIFS(Costos!$I:$I,Costos!$D:$D,">="&A10,Costos!$D:$D,"<"&EDATE(A10,1)) -> 29734616 | D10: =SUMIFS(Costos!$J:$J,Costos!$D:$D,">="&A10,Costos!$D:$D,"<"&EDATE(A10,1)) -> 1786912.5 | E10: =SUMIFS(Costos!$N:$N,Costos!$D:$D,">="&A10,Costos!$D:$D,"<"&EDATE(A10,1)) -> 31541540 | F10: =IFERROR(E10/$E$16,0) -> 0.082134063 | H10: GLOBAL-TEC S.A.S | I10: 900762275 | J10: =COUNTIFS(Costos!$E:$E,I10) -> 14 | K10: =SUMIFS(Costos!$N:$N,Costos!$E:$E,I10) -> 8247465.9 | L10: =IFERROR(K10/$E$16,0) -> 0.021476374
A11: =EDATE(A10,1) -> 45870 | B11: =COUNTIFS(Costos!$D:$D,">="&A11,Costos!$D:$D,"<"&EDATE(A11,1)) -> 56 | C11: =SUMIFS(Costos!$I:$I,Costos!$D:$D,">="&A11,Costos!$D:$D,"<"&EDATE(A11,1)) -> 32656329 | D11: =SUMIFS(Costos!$J:$J,Costos!$D:$D,">="&A11,Costos!$D:$D,"<"&EDATE(A11,1)) -> 1124381.6 | E11: =SUMIFS(Costos!$N:$N,Costos!$D:$D,">="&A11,Costos!$D:$D,"<"&EDATE(A11,1)) -> 33790703 | F11: =IFERROR(E11/$E$16,0) -> 0.087990878 | H11: TYU IMPORTACIONES S.A. | I11: 900181068 | J11: =COUNTIFS(Costos!$E:$E,I11) -> 6 | K11: =SUMIFS(Costos!$N:$N,Costos!$E:$E,I11) -> 8071062.9 | L11: =IFERROR(K11/$E$16,0) -> 0.021017021
A12: =EDATE(A11,1) -> 45901 | B12: =COUNTIFS(Costos!$D:$D,">="&A12,Costos!$D:$D,"<"&EDATE(A12,1)) -> 66 | C12: =SUMIFS(Costos!$I:$I,Costos!$D:$D,">="&A12,Costos!$D:$D,"<"&EDATE(A12,1)) -> 33979493 | D12: =SUMIFS(Costos!$J:$J,Costos!$D:$D,">="&A12,Costos!$D:$D,"<"&EDATE(A12,1)) -> 3270844.7 | E12: =SUMIFS(Costos!$N:$N,Costos!$D:$D,">="&A12,Costos!$D:$D,"<"&EDATE(A12,1)) -> 37258737 | F12: =IFERROR(E12/$E$16,0) -> 0.097021626 | H12: STEFANO ZINNO | I12: 700108357 | J12: =COUNTIFS(Costos!$E:$E,I12) -> 38 | K12: =SUMIFS(Costos!$N:$N,Costos!$E:$E,I12) -> 7221500 | L12: =IFERROR(K12/$E$16,0) -> 0.018804762
A13: =EDATE(A12,1) -> 45931 | B13: =COUNTIFS(Costos!$D:$D,">="&A13,Costos!$D:$D,"<"&EDATE(A13,1)) -> 70 | C13: =SUMIFS(Costos!$I:$I,Costos!$D:$D,">="&A13,Costos!$D:$D,"<"&EDATE(A13,1)) -> 37808641 | D13: =SUMIFS(Costos!$J:$J,Costos!$D:$D,">="&A13,Costos!$D:$D,"<"&EDATE(A13,1)) -> 1276540 | E13: =SUMIFS(Costos!$N:$N,Costos!$D:$D,">="&A13,Costos!$D:$D,"<"&EDATE(A13,1)) -> 39089143 | F13: =IFERROR(E13/$E$16,0) -> 0.101788 | H13: KLEYMAN YONATHAN VERGARA GONZALEZ | I13: 93397337 | J13: =COUNTIFS(Costos!$E:$E,I13) -> 31 | K13: =SUMIFS(Costos!$N:$N,Costos!$E:$E,I13) -> 6510000 | L13: =IFERROR(K13/$E$16,0) -> 0.016952018
A14: =EDATE(A13,1) -> 45962 | B14: =COUNTIFS(Costos!$D:$D,">="&A14,Costos!$D:$D,"<"&EDATE(A14,1)) -> 64 | C14: =SUMIFS(Costos!$I:$I,Costos!$D:$D,">="&A14,Costos!$D:$D,"<"&EDATE(A14,1)) -> 24941632 | D14: =SUMIFS(Costos!$J:$J,Costos!$D:$D,">="&A14,Costos!$D:$D,"<"&EDATE(A14,1)) -> 2392934.6 | E14: =SUMIFS(Costos!$N:$N,Costos!$D:$D,">="&A14,Costos!$D:$D,"<"&EDATE(A14,1)) -> 27344365 | F14: =IFERROR(E14/$E$16,0) -> 0.071204635 | H14: FCE COLOMBIA S A S | I14: 901718849 | J14: =COUNTIFS(Costos!$E:$E,I14) -> 4 | K14: =SUMIFS(Costos!$N:$N,Costos!$E:$E,I14) -> 5064232 | L14: =IFERROR(K14/$E$16,0) -> 0.013187243
A15: =EDATE(A14,1) -> 45992 | B15: =COUNTIFS(Costos!$D:$D,">="&A15,Costos!$D:$D,"<"&EDATE(A15,1)) -> 72 | C15: =SUMIFS(Costos!$I:$I,Costos!$D:$D,">="&A15,Costos!$D:$D,"<"&EDATE(A15,1)) -> 69061226 | D15: =SUMIFS(Costos!$J:$J,Costos!$D:$D,">="&A15,Costos!$D:$D,"<"&EDATE(A15,1)) -> 10952720 | E15: =SUMIFS(Costos!$N:$N,Costos!$D:$D,">="&A15,Costos!$D:$D,"<"&EDATE(A15,1)) -> 80016983 | F15: =IFERROR(E15/$E$16,0) -> 0.20836396 | H15: Otros (65 prov.) | J15: =B16-SUM(J5:J14) -> 222 | K15: =E16-SUM(K5:K14) -> 50285257 | L15: =IFERROR(K15/$E$16,0) -> 0.13094264
A16: TOTAL | B16: =SUM(B5:B15) -> 554 | C16: =SUM(C5:C15) -> 3.5910369e+08 | D16: =SUM(D5:D15) -> 24769170 | E16: =SUM(E5:E15) -> 3.8402507e+08 | F16: =IFERROR(E16/$E$16,0) -> 1 | H16: TOTAL | J16: =SUM(J5:J15) -> 554 | K16: =SUM(K5:K15) -> 3.8402507e+08 | L16: =IFERROR(K16/$E$16,0) -> 1
H19: Indicadores clave
H20: Costo total (COP) | I20: =E16 -> 3.8402507e+08
H21: Total facturas | I21: =B16 -> 554
H22: Promedio mensual | I22: =AVERAGE(E5:E15) -> 34911370
H23: Factura promedio | I23: =E16/B16 -> 693186.05
H24: Mes de mayor costo | I24: =INDEX(A5:A15,MATCH(MAX(E5:E15),E5:E15,0)) -> 45992
H25: Mayor proveedor | I25: =H5&" ("&TEXT(L5,"0.0%")&")" -> IMPRESISTEM S A S (43.3%)

Sheet Hoja1
A1: NIT Emisor | B1: Nombre Emisor | C1: Suma de SUBTOTAL | D1: Suma de IVA | E1: Suma de IC | F1: Suma de INC | G1: Suma de INC Bolsas
A2: 3486666 | B2: RAMON ALCIDES CIFUENTES SERNA | C2: 3710000 | D2: 0 | E2: 0 | F2: 0 | G2: 0
A3: 8026157 | B3: ANDRES FELIPE VELEZ MUÑOZ | C3: 207000 | D3: 39330 | E3: 0 | F3: 0 | G3: 0
A4: 32257553 | B4: ROLDAN OLGA AMPARO | C4: 1500000 | D4: 0 | E4: 0 | F4: 0 | G4: 0
A5: 43645742 | B5: ARBELAEZ GIRALDO GLORIA CRISTINA | C5: 531092.38 | D5: 100907.55 | E5: 0 | F5: 0 | G5: 0
A6: 70561688 | B6: DIEGO ALONSO MURILLO GUZMAN | C6: 16000 | D6: 3040 | E6: 0 | F6: 0 | G6: 0
A7: 70780282 | B7: JOSE ANGEL LOPEZ VILLA | C7: 16000 | D7: 0 | E7: 0 | F7: 0 | G7: 0
A8: 70978458 | B8: PEREZ PEREZ JAIDER ESNEIDER | C8: 29411.76 | D8: 5588.23 | E8: 0 | F8: 0 | G8: 0
A9: 71388800 | B9: ARISTIZABAL SERNA DANIEL ALEJANDRO | C9: 8403 | D9: 1597 | E9: 0 | F9: 0 | G9: 0
A10: 91076199 | B10: VARGAS MIRANDA LUIS FERNANDO | C10: 429411.77 | D10: 81588.23 | E10: 0 | F10: 0 | G10: 0
A11: 93397337 | B11: KLEYMAN YONATHAN VERGARA GONZALEZ | C11: 6510000 | D11: 0 | E11: 0 | F11: 0 | G11: 0
A12: 700108357 | B12: STEFANO ZINNO | C12: 7221500 | D12: 0 | E12: 0 | F12: 0 | G12: 0
A13: 800091549 | B13: IMPRESISTEM S A S | C13: 166193551 | D13: 65930 | E13: 0 | F13: 0 | G13: 0
... A65: 901575358 | B65: CLOVER COMPANY S.A.S | C65: 3783024.1 | D65: 718774.58 | E65: 0 | F65: 0 | G65: 0
A66: 901606621 | B66: LA VELERIA PARAFIN S.A.S. | C66: 163697.4 | D66: 31102.51 | E66: 0 | F66: 0 | G66: 0 | I66: PAGADO | J66: SUB | K66: RT | L66: 2205
A67: 901649254 | B67: JSA DISTRIBUCIONES S.A.S. | C67: 52220152 | D67: 9921828.9 | E67: 0 | F67: 0 | G67: 0 | I67: 3130000 | J67: =+GETPIVOTDATA("Suma de SUBTOTAL",$A$1,"NIT Emisor",901649254,"Nombre Emisor","JSA DISTRIBUCIONES S.A.S.")+GETPIVOTDATA("Suma de IVA",$A$1,"NIT Emisor",901649254,"Nombre Emisor","JSA DISTRIBUCIONES S.A.S.") -> 62141981 | K67: =+GETPIVOTDATA("Suma de SUBTOTAL",$A$1,"NIT Emisor",901649254,"Nombre Emisor","JSA DISTRIBUCIONES S.A.S.")*2.5% -> 1305503.8 | L67: =+J67-I67-K67 -> 57706477
A68: 901660770 | B68: CRISPINO S.A.S. | C68: 185881.47 | D68: 0 | E68: 0 | F68: 13518.51 | G68: 0
A69: 901718849 | B69: FCE COLOMBIA S A S | C69: 5064232 | D69: 0 | E69: 0 | F69: 0 | G69: 0
A70: 901784030 | B70: BOMBA FOODS SAS | C70: 161759.25 | D70: 0 | E70: 0 | F70: 12940.75 | G70: 0
A71: 901939945 | B71: JOTTAFOODS SAS | C71: 197075.65 | D71: 35924.37 | E71: 0 | F71: 0 | G71: 0
A72: 901972453 | B72: TECNOVÍA SAS | C72: 92782 | D72: 17628.58 | E72: 0 | F72: 0 | G72: 0
A73: 1003880015 | B73: PAEZ BALLESTEROS CESAR NICOLAS | C73: 202000 | D73: 0 | E73: 0 | F73: 0 | G73: 0
A74: 1128277256 | B74: ARISTIZABAL GOMEZ JUAN DAVID | C74: 518487.4 | D74: 98512.61 | E74: 0 | F74: 0 | G74: 0
A75: 1128404762 | B75: Bodega Digital Medellin | C75: 60000 | D75: 11400 | E75: 0 | F75: 0 | G75: 0
A76: Total general | C76: 3.5878269e+08 | D76: 24769170 | E76: 5844 | F76: 146053.18 | G76: 318
C79: =+GETPIVOTDATA("Suma de SUBTOTAL",$A$1)+GETPIVOTDATA("Suma de IC",$A$1)+GETPIVOTDATA("Suma de INC",$A$1)+GETPIVOTDATA("Suma de INC Bolsas",$A$1) -> 3.589349e+08 | D79: Costos
C80: =+GETPIVOTDATA("Suma de SUBTOTAL",$A$1)-C79 -> -152215.18 | G80: =+GETPIVOTDATA("Suma de INC Bolsas",$A$1)+GETPIVOTDATA("Suma de INC",$A$1)+GETPIVOTDATA("Suma de IC",$A$1) -> 152215.18 | H80: ok
